Workbook

Sheet discount_rate
B1: discount_rate | C1: unit | D1: reference | E1: comment
A2: Photovoltaic | B2: 0.057 | C2: fraction of capex | D2: TEMOA-Italy | E2: Paper di supporto
A3: WindTurbine_Onshore_1500 | B3: 0.076 | C3: fraction of capex | D3: TEMOA-Italy | E3: Paper di supporto
A4: NuclearPlant | B4: 0.045 | C4: fraction of capex | D4: TEMOA-Italy
A5: Storage_Battery | B5: 0.08 | C5: fraction of capex | D5: TEMOA-Italy
A6: Hydro_Reservoir | B6: 0.052 | C6: fraction of capex | D6: TEMOA-Italy | E6: Paper di supporto
A7: GasTurbine_simple | B7: 0.027 | C7: fraction of capex | D7: TEMOA-Italy | E7: Paper di supporto
A8: CoalPlant | B8: 0.062 | C8: fraction of capex | D8: TEMOA-Italy | E8: Paper di supporto
A9: PumpedHydro_Open | B9: 0.052 | C9: fraction of capex | D9: TEMOA-Italy | E9: Paper di supporto
A10: CompressedAirStorage | B10: 0.08 | C10: fraction of capex | D10: no source, just put the same as Li-ion
D17: =PMT(0.07,25,1) -> -0.085810517

Sheet OPEX
B1: OPEX | C1: unit | D1: reference | E1: comment
A2: Photovoltaic | B2: =1.7275/100 -> 0.017275 | C2: fraction of capex | D2: PyPSA/technology-data | E2: 2025-Mixed investment costs based on average of 50% 'solar-rooftop' and 50% 'solar-utility'
A3: WindTurbine_Onshore_1500 | B3: =1.2347/100 -> 0.012347 | C3: fraction of capex | D3: PyPSA/technology-data | E3: 2025
A4: NuclearPlant | B4: 0.033 | C4: fraction of capex | E4: assumed same as coal
A5: Storage_Battery | B5: 0.017 | C5: fraction of capex | E5: assumed same as PV
A6: Hydro_Reservoir | B6: =1/100 -> 0.01 | C6: fraction of capex | D6: PyPSA/technology-data | E6: 2025
A7: GasTurbine_simple | B7: =3.313/100 -> 0.03313 | C7: fraction of capex | D7: PyPSA/technology-data | E7: 2025, Gas turbine, simple cycle
A8: CoalPlant | B8: =1.6316/100 -> 0.016316 | C8: fraction of capex | D8: PyPSA/technology-data | E8: 2025
A9: PumpedHydro_Open | B9: =0.43/100 -> 0.0043 | C9: fraction of capex | D9: PyPSA/technology-data | E9: 2025
A10: CompressedAirStorage | B10: 0.043 | C10: fraction of capex | D10: DoE

Sheet CAPEX
B1: CAPEX | C1: unit | D1: reference | E1: comment | F1: CAPEX eur2020 | G1: eur2020_to_2025
A2: Photovoltaic | B2: =F2*$G$2 -> 591394.5 | C2: EUR/MW | D2: PyPSA/technology-data | E2: 2025-Mixed investment costs based on average of 50% 'solar-rooftop' and 50% 'solar-utility' | F2: 473115.6 | G2: 1.25
A3: WindTurbine_Onshore_1500 | B3: =F3*$G$2 -> 2265516.7 | C3: EUR/(1.5MW_turbine) | D3: PyPSA/technology-data | E3: 2025 | F3: =1208275.556*1.5 -> 1812413.3
A4: NuclearPlant | B4: =F4*$G$2 -> 8296176.2 | C4: EUR/MW | D4: Princeton | E4: Fonte considerata la più realistica da Lorenzo | F4: 6636941
A5: Storage_Battery | B5: =F5*$G$2 -> 190034.85 | C5: EUR/MWh | D5: PyPSA/technology-data | E5: 2025, 2 h, Average utility-home | F5: =506759.606*0.3 -> 152027.88
A6: Hydro_Reservoir | B6: =F6*$G$2/631 -> 5137.2666 | C6: EUR/MWh (scaled with 631h as the average storage time of hydro in italy) | D6: PyPSA/technology-data | E6: 2025 | F6: 2593292.2
A7: GasTurbine_simple | B7: =F7*$G$2 -> 806232.55 | C7: EUR/MW | D7: PyPSA/technology-data | E7: 2025, Gas turbine, simple cycle | F7: 644986.04
A8: CoalPlant | B8: =F8*$G$2 -> 2636363.1 | C8: EUR/MW | D8: PyPSA/technology-data | E8: 2025 | F8: 2109090.5
A9: PumpedHydro_Open | B9: =F9*$G$2 -> 75623.133 | C9: EUR/MWh | D9: PyPSA/technology-data | E9: 2025 | F9: 60498.506
A10: CompressedAirStorage | B10: =raw_data_techs!I41 -> 5995.8648 | C10: EUR/MWh | D10: DoE | E10: 2025,data for capex_power to be input manually in json using values from the sheet "raw_data_techs"

Sheet Fuel_cost
B1: fuel_cost | C1: unit | D1: reference | E1: comment
A2: costo_combustibile_gas | B2: 27.538557 | C2: EUR/MWh | D2: World Bank | E2: Average annual value, 2024
A3: costo_combustibile_carbone | B3: 10.331146 | C3: EUR/MWh | D3: World Bank | E3: Average annual value, 2024
A4: costo_combustibile_nucleare | B4: 4.8 | C4: EUR/MWh | D4: World Nuclear Association, EIA, NREL | E4: Average between values found (2020-2021)

Sheet Transmission_abroad
B1: capacity | C1: price | D1: emission_factor_t/MWh | E1: reference | F1: comment
A2: NORD | B2: 10138 | C2: 100 | D2: 0 | E2: electricity map | F2: Include francia, svizzera, slovenia, austria
A3: CALA | B3: 0 | C3: 0 | D3: 0
A4: CNOR | B4: 0 | C4: 0 | D4: 0
A5: CSUD | B5: 600 | C5: 0 | D5: 0 | F5: montenegro
A6: SUD | B6: 500 | C6: 100 | D6: 0 | E6: electricity map | F6: grecia
A7: SARD | B7: 0 | C7: 0 | D7: 0 | F7: tunisia
A8: SICI | B8: 600 | C8: 0 | D8: 0

Sheet raw_data_commodity
A1: Entry voice | B1: Year | C1: Value | D1: Unit | E1: Reference | F1: Comment | G1: Model input value | H1: Model unit
A2: costo combustibile gas | B2: 2018 | C2: 7.5414094 | D2: ($2010/mmbtu) | E2: World Bank | F2: Natural gas, Europe | G2: =C2*$M$3/$M$4 -> 21.805546 | H2: (€2020/MWh) | L2: Conversion | M2: Multiplier | N2: Reference
A3: costo combustibile gas | B3: 2019 | C3: 4.827454 | D3: ($2010/mmbtu) | E3: World Bank | F3: Natural gas, Europe | G3: =C3*$M$3/$M$4 -> 13.958302 | H3: (€2020/MWh) | L3: €2020/$2010 | M3: 0.85 | N3: Harmonised Index of Consumer Prices (HICP)
A4: costo combustibile gas | B4: 2020 | C4: 3.3115669 | D4: ($2010/mmbtu) | E4: World Bank | F4: Natural gas, Europe | G4: =C4*$M$3/$M$4 -> 9.5752027 | H4: (€2020/MWh) | L4: MWh/mmbtu | M4: 0.293971
A5: costo combustibile gas | B5: 2021 | C5: 14.73115 | D5: ($2010/mmbtu) | E5: World Bank | F5: Natural gas, Europe | G5: =C5*$M$3/$M$4 -> 42.594261 | H5: (€2020/MWh) | L5: MWh/kcal | M5: =1.622*10^-6 -> 1.622e-06
A6: costo combustibile gas | B6: 2022 | C6: 34.346664 | D6: ($2010/mmbtu) | E6: World Bank | F6: Natural gas, Europe | G6: =C6*$M$3/$M$4 -> 99.311376 | H6: (€2020/MWh) | L6: Standard heating value of thermal coal (kcal/kg) | M6: 6000 | N6: World Bank
A7: costo combustibile gas | B7: 2023 | C7: 11.492904 | D7: ($2010/mmbtu) | E7: World Bank | F7: Natural gas, Europe | G7: =C7*$M$3/$M$4 -> 33.231061 | H7: (€2020/MWh) | L7: €2020/$2021 | M7: 0.82 | N7: Harmonised Index of Consumer Prices (HICP)
A8: costo combustibile gas | B8: 2024 | C8: 9.5241612 | D8: ($2010/mmbtu) | E8: World Bank | F8: Natural gas, Europe | G8: =C8*$M$3/$M$4 -> 27.538557 | H8: (€2020/MWh) | L8: €2020/$2020 | M8: 0.88 | N8: Harmonised Index of Consumer Prices (HICP)
A9: costo combustibile carbone | B9: 2018 | C9: 105.06823 | D9: ($2010/mt) | E9: World Bank | F9: Coal, Australian | G9: =C9*$M$3/$M$6/$M$5/1000 -> 9.1767362 | H9: (€2020/MWh)
A10: costo combustibile carbone | B10: 2019 | C10: 78.292957 | D10: ($2010/mt) | E10: World Bank | F10: Coal, Australian | G10: =C10*$M$3/$M$6/$M$5/1000 -> 6.8381641 | H10: (€2020/MWh)
A11: costo combustibile carbone | B11: 2020 | C11: 62.088866 | D11: ($2010/mt) | E11: World Bank | F11: Coal, Australian | G11: =C11*$M$3/$M$6/$M$5/1000 -> 5.422887 | H11: (€2020/MWh)
A12: costo combustibile carbone | B12: 2021 | C12: 126.1883 | D12: ($2010/mt) | E12: World Bank | F12: Coal, Australian | G12: =C12*$M$3/$M$6/$M$5/1000 -> 11.021378 | H12: (€2020/MWh)
A13: costo combustibile carbone | B13: 2022 | C13: 293.6512 | D13: ($2010/mt) | E13: World Bank | F13: Coal, Australian | G13: =C13*$M$3/$M$6/$M$5/1000 -> 25.647711 | H13: (€2020/MWh)
A14: costo combustibile carbone | B14: 2023 | C14: 151.42784 | D14: ($2010/mt) | E14: World Bank | F14: Coal, Australian | G14: =C14*$M$3/$M$6/$M$5/1000 -> 13.225818 | H14: (€2020/MWh)
A15: costo combustibile carbone | B15: 2024 | C15: 118.28555 | D15: ($2010/mt) | E15: World Bank | F15: Coal, Australian | G15: =C15*$M$3/$M$6/$M$5/1000 -> 10.331146 | H15: (€2020/MWh)
A16: costo combustibile nucleare | B16: 2021 | C16: 0.46 | D16: (c$2021/kWh) | E16: World Nuclear Association | G16: =C16*M7/100*1000 -> 3.772 | H16: (€2020/MWh)
A17: costo combustibile nucleare | B17: 2020-2040 | C17: 7 | D17: ($2020/MWh) | E17: NREL | G17: =C17*M7 -> 5.74 | H17: (€2020/MWh)
A18: costo combustibile nucleare | B18: 2021 | C18: 0.61 | D18: (c$2021/kWh) | E18: EIA | G18: =C18*M7/100*1000 -> 5.002 | H18: (€2020/MWh)

Sheet raw_data_techs
A1: Entry voice | B1: Tech type | C1: Year | D1: Value | E1: Unit | F1: Reference | G1: Comment 1 | H1: Comment 2 | I1: Model input value | J1: Model unit
A2: CAPEX solare | B2: Utility scale | C2: 2020 | D2: 1333 | E2: (M$2020/GW) | F2: TEMOA-Italy | G2: Dati elaborati da NREL | I2: =D2*$Q$3*10^3 -> 1173040 | J2: (€2020/MW) | P2: Conversion | Q2: Multiplier | R2: Reference
A3: CAPEX solare | B3: Utility scale | C3: 2030 | D3: 754 | E3: (M$2020/GW) | F3: TEMOA-Italy | G3: Dati elaborati da NREL | I3: =D3*$Q$3*10^3 -> 663520 | J3: (€2020/MW) | P3: €2020/$2020 | Q3: 0.88 | R3: Harmonised Index of Consumer Prices (HICP)
A4: CAPEX solare | B4: General | C4: 2025 | D4: 676.5703 | E4: (M$2020/GW) | F4: PyPSA/technology-data | G4: Dati elaborati da Danish Energy Agency | H4: Mixed investment costs based on average of 50% 'solar-rooftop' and 50% 'solar-utility' | I4: =D4*10^3 -> 676570.3 | J4: (€2020/MW) | P4: €2020/€2015 | Q4: 1.06 | R4: Harmonised Index of Consumer Prices (HICP)
A5: CAPEX solare | B5: Utility | C5: 2025 | D5: 473.1156 | E5: (M$2020/GW) | F5: PyPSA/technology-data | G5: Dati elaborati da Danish Energy Agency | I5: =D5*10^3 -> 473115.6 | J5: (€2020/MW) | P5: €2020/€2010 | Q5: 1.14 | R5: Harmonised Index of Consumer Prices (HICP)
A6: CAPEX eolico | B6: Onshore | C6: 2020 | D6: 1462 | E6: (M$2020/GW) | F6: TEMOA-Italy | G6: Dati elaborati da NREL | I6: =D6*$Q$3*10^3 -> 1286560 | J6: (€2020/MW) | P6: €2020/€2024 | Q6: 0.82 | R6: Harmonised Index of Consumer Prices (HICP)
A7: CAPEX eolico | B7: Onshore | C7: 2030 | D7: 956 | E7: (M$2020/GW) | F7: TEMOA-Italy | G7: Dati elaborati da NREL | I7: =D7*$Q$3*10^3 -> 841280 | J7: (€2020/MW) | P7: €2020/€2018 | Q7: 1.02 | R7: Harmonised Index of Consumer Prices (HICP)
A8: CAPEX eolico | B8: Onshore | C8: 2025 | D8: 1139.8826 | E8: (M$2015/GW) | F8: PyPSA/technology-data | G8: Dati elaborati da Danish Energy Agency | I8: =D8*$Q$4*10^3 -> 1208275.6 | J8: (€2020/MW) | P8: €2018/$2018 | Q8: =1/1.145 -> 0.87336245 | R8: Banca d’Italia
A9: CAPEX eolico | B9: Offshore | C9: 2020 | D9: 3739 | E9: (M$2020/GW) | F9: TEMOA-Italy | G9: Dati elaborati da NREL | I9: =D9*$Q$3*10^3 -> 3290320 | J9: (€2020/MW) | P9: €2016/$2016 | Q9: =1/1.0541 -> 0.9486766 | R9: Banca d’Italia
A10: CAPEX eolico | B10: Offshore | C10: 2030 | D10: 2758 | E10: (M$2020/GW) | F10: TEMOA-Italy | G10: Dati elaborati da NREL | I10: =D10*$Q$3*10^3 -> 2427040 | J10: (€2020/MW) | P10: €2020/€2016 | Q10: 1.06 | R10: Harmonised Index of Consumer Prices (HICP)
A11: CAPEX eolico | B11: Offshore | C11: 2025 | D11: 1769.1171 | E11: (M$2020/GW) | F11: PyPSA/technology-data | G11: Dati elaborati da Danish Energy Agency | I11: =D11*10^3 -> 1769117.1 | J11: (€2020/MW)
A12: CAPEX eolico | B12: Offshore acque profonde | C12: 2020 | D12: 4049 | E12: (M$2020/GW) | F12: TEMOA-Italy | G12: Dati elaborati da NREL | I12: =D12*$Q$3*10^3 -> 3563120 | J12: (€2020/MW)
A13: CAPEX eolico | B13: Offshore acque profonde | C13: 2030 | D13: 3467 | E13: (M$2020/GW) | F13: TEMOA-Italy | G13: Dati elaborati da NREL | I13: =D13*$Q$3*10^3 -> 3050960 | J13: (€2020/MW)
A14: CAPEX nucleare | B14: AP1000 | C14: 2035 | D14: 6160 | E14: (M$2020/GW) | F14: TEMOA-Italy | G14: Dati elaborati da NREL | H14: Include il decommissioning | I14: =D14*$Q$3*10^3 -> 5420800 | J14: (€2020/MW)
A15: CAPEX nucleare | B15: AP1000 | C15: 2050 | D15: 5500 | E15: (M$2020/GW) | F15: TEMOA-Italy | G15: Dati elaborati da NREL | H15: Include il decommissioning | I15: =D15*$Q$3*10^3 -> 4840000 | J15: (€2020/MW)
A16: CAPEX nucleare | B16: SMR | C16: 2035 | D16: 6820 | E16: (M$2020/GW) | F16: TEMOA-Italy | G16: Dati elaborati da NREL | H16: Include il decommissioning | I16: =D16*$Q$3*10^3 -> 6001600 | J16: (€2020/MW)
A17: CAPEX nucleare | B17: SMR | C17: 2050 | D17: 6050 | E17: (M$2020/GW) | F17: TEMOA-Italy | G17: Dati elaborati da NREL | H17: Include il decommissioning | I17: =D17*$Q$3*10^3 -> 5324000 | J17: (€2020/MW)
A18: CAPEX idroelettrico | C18: 2025 | D18: 2274.8177 | E18: (M€2010/GW) | F18: PyPSA/technology-data | G18: Dati elaborati da Danish Energy Agency | I18: =D18*$Q$5*10^3 -> 2593292.2 | J18: (€2020/MW)
A19: CAPEX PHS | C19: 2025 | D19: 57074.062 | E19: (€2015/MWh) | F19: PyPSA/technology-data | G19: Dati elaborati da Danish Energy Agency | I19: =D19*$Q$4 -> 60498.506 | J19: (€2020/MWh)
A20: CAPEX carbone | B20: Ciclo a vapore | C20: 2020 | D20: 3075 | E20: (M$2020/GW) | F20: TEMOA-Italy | G20: Dati elaborati da NREL | I20: =D20*$Q$3*10^3 -> 2706000 | J20: (€2020/MW)
A21: CAPEX carbone | B21: Ciclo a vapore | C21: 2030 | D21: 2240 | E21: (M$2020/GW) | F21: TEMOA-Italy | G21: Dati elaborati da NREL | I21: =D21*$Q$3*10^3 -> 1971200 | J21: (€2020/MW)
A22: CAPEX carbone | C22: 2025 | D22: 1989.708 | E22: (M€2015/GW) | F22: PyPSA/technology-data | G22: Dati elaborati da Danish Energy Agency | I22: =D22*$Q$4*10^3 -> 2109090.5 | J22: (€2020/MW)
A23: CAPEX gas | B23: Ciclo combinato | C23: 2020 | D23: 1038 | E23: (M$2020/GW) | F23: TEMOA-Italy | G23: Dati elaborati da NREL | I23: =D23*$Q$3*10^3 -> 913440 | J23: (€2020/MW)
A24: CAPEX gas | B24: Ciclo combinato | C24: 2030 | D24: 838 | E24: (M$2020/GW) | F24: TEMOA-Italy | G24: Dati elaborati da NREL | I24: =D24*$Q$3*10^3 -> 737440 | J24: (€2020/MW)
A25: CAPEX gas | B25: Gas turbine, simple cycle | C25: 2025 | D25: 608.4774 | E25: (M€2015/GW) | F25: PyPSA/technology-data | G25: Dati elaborati da Danish Energy Agency | I25: =D25*$Q$4*10^3 -> 644986.04 | J25: (€2020/MW)
A26: CAPEX nucleare | B26: EPR | C26: 2025 | D26: 5350 | E26: (M$2025/GW) | F26: IAEA | G26: EPR Francia | H26: Overnight cost suggerito da Lorenzo Mazzocco, portato dal 2020 al 2025 tramite inflazione di circa il 33% (vedi messaggio discord su Coordinamento energia) | I26: =D26*$Q$3*10^3*0.67 -> 3154360 | J26: (€2020/MW)
A27: CAPEX batterie Li-ion | B27: 2h | C27: 2020 | D27: 988.3217 | E27: (M$2020/GW) | F27: TEMOA-Italy | G27: Dati elaborati da NREL | H27: Due componenti di costo considerate: power capital cost (€/MW) e energy capital cost (€/MWh). Quest'ultimo moltiplicato per uno "storage duration" di 2 ore. Per ulteriori info, vedere questo paper | I27: =D27*$Q$3*10^3 -> 869723.1 | J27: (€2020/MW)
A28: CAPEX batterie Li-ion | B28: 2h | C28: 2030 | D28: 681.62248 | E28: (M$2020/GW) | F28: TEMOA-Italy | G28: Dati elaborati da NREL | H28: Due componenti di costo considerate: power capital cost (€/MW) e energy capital cost (€/MWh). Quest'ultimo moltiplicato per uno "storage duration" di 2 ore. Per ulteriori info, vedere questo paper | I28: =D28*$Q$3*10^3 -> 599827.78 | J28: (€2020/MW)
A29: CAPEX batterie Li-ion | B29: 2h | C29: 2050 | D29: 681.62248 | E29: (M$2020/GW) | F29: TEMOA-Italy | G29: Dati elaborati da NREL | H29: Due componenti di costo considerate: power capital cost (€/MW) e energy capital cost (€/MWh). Quest'ultimo moltiplicato per uno "storage duration" di 2 ore. Per ulteriori info, vedere questo paper | I29: =D29*$Q$3*10^3 -> 599827.78 | J29: (€2020/MW)
A30: CAPEX batterie Li-ion | B30: 4h | C30: 2020 | D30: 1727.2344 | E30: (M$2020/GW) | F30: TEMOA-Italy | G30: Dati elaborati da NREL | H30: Due componenti di costo considerate: power capital cost (€/MW) e energy capital cost (€/MWh). Quest'ultimo moltiplicato per uno "storage duration" di 4 ore. Per ulteriori info, vedere questo paper | I30: =D30*$Q$3*10^3 -> 1519966.3 | J30: (€2020/MW)
A31: CAPEX batterie Li-ion | B31: 4h | C31: 2030 | D31: 1173.7258 | E31: (M$2020/GW) | F31: TEMOA-Italy | G31: Dati elaborati da NREL | H31: Due componenti di costo considerate: power capital cost (€/MW) e energy capital cost (€/MWh). Quest'ultimo moltiplicato per uno "storage duration" di 4 ore. Per ulteriori info, vedere questo paper | I31: =D31*$Q$3*10^3 -> 1032878.7 | J31: (€2020/MW)
A32: CAPEX batterie Li-ion | B32: 4h | C32: 2050 | D32: 1173.7258 | E32: (M$2020/GW) | F32: TEMOA-Italy | G32: Dati elaborati da NREL | H32: Due componenti di costo considerate: power capital cost (€/MW) e energy capital cost (€/MWh). Quest'ultimo moltiplicato per uno "storage duration" di 4 ore. Per ulteriori info, vedere questo paper | I32: =D32*$Q$3*10^3 -> 1032878.7 | J32: (€2020/MW)
A33: CAPEX batterie Li-ion | B33: 2 h - utility | C33: 2025 | D33: =197.8874*2 -> 395.7748 | E33: (M€2015/GW) | F33: PyPSA/technology-data | G33: Dati elaborati da Danish Energy Agency | H33: Durata dovrebbe essere di 2 h | I33: =D33*$Q$4*10^3 -> 419521.29 | J33: (€2020/MW)
A34: CAPEX batterie Li-ion | B34: 2 h - home | C34: 2025 | D34: =280.1877*2 -> 560.3754 | E34: (M€2015/GW) | F34: PyPSA/technology-data | G34: Dati elaborati da Danish Energy Agency | H34: Durata dovrebbe essere di 2 h | I34: =D34*$Q$4*10^3 -> 593997.92 | J34: (€2020/MW)
A35: CAPEX nucleare | B35: EPR | C35: 2020 | D35: 4013 | E35: (M$2018/GW) | F35: IAEA | G35: EPR Francia, nuova costruzione | I35: =D35*Q8*Q7 -> 3574.8996 | J35: (€2020/MW)
A36: CAPEX nucleare | B36: EPR | C36: 2024 | D36: 10000 | E36: (M€2024/GW) | F36: S&P | G36: EPR EU, nuova costruzione | I36: =D36*Q6 -> 8200 | J36: (€2020/MW)
A37: CAPEX nucleare | C37: 2020 | D37: 6600 | E37: ($2016/GW) | F37: Princeton | G37: Generico “Nuclear power” | I37: =D37*Q10*Q9 -> 6636.9415 | J37: (€2020/MW)
A38: Capex power LDES | B38: LiquidAirStorage | C38: 2030 | D38: 2000000 | E38: EUR2022/MW | F38: EU | I38: =D38*1.11 -> 2220000 | J38: (€2025/MW)
A39: Capex energy LDES | B39: LiquidAirStorage | C39: 2030 | D39: 450000 | E39: EUR2022/MWh | F39: EU | I39: =D39*1.11 -> 499500 | J39: (€2025/MWh)
A40: Capex power LDES | B40: CompressedAirStorage | C40: 2030 | D40: =1061*1000 -> 1061000 | E40: $2022/MW | F40: DoE | H40: Capex per charging e discharging | I40: =D40*0.951*1.11 -> 1120002.2 | J40: (€2025/MW)
...

Sheet resulting_lcoe_input
B1: discount rate | C1: capex [eur/MW] | D1: opex_fixed | E1: lifetime | F1: capacity_factor | G1: annualization_factor | H1: lcoe [eur/MWh]
A2: Photovoltaic | B2: =discount_rate!B2 -> 0.057 | C2: =CAPEX!B2 -> 591394.5 | D2: =OPEX!B2 -> 0.017275 | E2: 20 | F2: 0.15 | G2: =PMT(B2,E2,-1) -> 0.085073306 | H2: =C2*(D2+G2)/(8760*F2*1) -> 46.064099
A3: WindTurbine_Onshore_1500 | B3: =discount_rate!B3 -> 0.076 | C3: =CAPEX!B3/1.5 -> 1510344.4 | D3: =OPEX!B3 -> 0.012347 | E3: 25 | F3: 0.25 | G3: =PMT(B3,E3,-1) -> 0.090498958 | H3: =C3*(D3+G3)/(8760*F3*1) -> 70.928229
A4: NuclearPlant | B4: =discount_rate!B4 -> 0.045 | C4: =CAPEX!B4 -> 8296176.2 | D4: =OPEX!B4 -> 0.033 | E4: 60 | F4: 0.85 | G4: =PMT(B4,E4,-1) -> 0.048454256 | H4: =C4*(D4+G4)/(8760*F4*1) -> 90.754615
